<mujoco model="surenav">
    <compiler angle="radian" inertiafromgeom="true"/>
    <default>
        <joint armature="1" damping="1" limited="true"/>
        <geom conaffinity="1" condim="1" contype="1" margin="0.001" material="geom" rgba="0.8 0.6 .4 1"/>
        <motor ctrllimited="true" ctrlrange="-1.57 1.57"/>
    </default>
    <option integrator="RK4" iterations="50" solver="PGS" timestep="0.003">
    </option>
    <size nkey="5" nuser_geom="1"/>
    <visual>
        <map fogend="5" fogstart="3"/>
    </visual>
    <asset>
        <mesh name="r_hip_yaw_link" file="r_hip_yaw_link.STL" />
        <mesh name="r_hip_roll_link" file="r_hip_roll_link.STL" />
        <mesh name="r_hip_pitch_link" file="r_hip_pitch_link.STL" />
        <mesh name="r_knee_link" file="r_knee_link.STL" />
        <mesh name="r_ankle_pitch_link" file="r_ankle_pitch_link.STL" />
        <mesh name="r_ankle_roll_link" file="r_ankle_roll_link.STL" />
        <mesh name="l_hip_yaw_link" file="l_hip_yaw_link.STL" />
        <mesh name="l_hip_roll_link" file="l_hip_roll_link.STL" />
        <mesh name="l_hip_pitch_link" file="l_hip_pitch_link.STL" />
        <mesh name="l_knee_link" file="l_knee_link.STL" />
        <mesh name="l_ankle_pitch_link" file="l_ankle_pitch_link.STL" />
        <mesh name="l_ankle_roll_link" file="l_ankle_roll_link.STL" />

        <texture builtin="gradient" height="100" rgb1=".4 .5 .6" rgb2="0 0 0" type="skybox" width="100"/>
        
        <texture builtin="flat" height="1278" mark="cross" markrgb="1 1 1" name="texgeom" random="0.01" rgb1="0.8 0.6 0.4" rgb2="0.8 0.6 0.4" type="cube" width="127"/>
        <texture builtin="checker" height="100" name="texplane" rgb1="0 0 0" rgb2="0.8 0.8 0.8" type="2d" width="100"/>
        <material name="MatPlane" reflectance="0.5" shininess="1" specular="1" texrepeat="60 60" texture="texplane"/>
        <material name="geom" texture="texgeom" texuniform="true"/>
    </asset>

    <worldbody>
        <!-- Ground -->
        <light cutoff="100" diffuse="1 1 1" dir="-0 0 -1.3" directional="true" exponent="1" pos="0 0 1.3" specular=".1 .1 .1"/>
        <geom condim="3" friction="1 .1 .1" material="MatPlane" name="floor" pos="0 0 0" rgba="0.8 0.9 0.8 1" size="20 20 0.125" type="plane"/>

        <!-- Surena V Lower Limb Robot Model-->
        <body name="torso" pos="0 0 0.93">
            <joint armature="0" damping="0" limited="false" name="root" pos="0 0 0" stiffness="0" type="free"/>
            <geom size="0.1 0.15 0.025" type="box" pos="0 0 0" rgba="0.752941 0.752941 0.752941 1" />
            <body name="r_hip_yaw_link" pos="0.016506 -0.1 -0.0256">
                <inertial pos="-0.07623 0.00014361 -0.090014" quat="0.37896 0.595667 0.598751 0.378242" mass="3.1729" diaginertia="0.0195846 0.0170547 0.00712107" />
                <joint name="r_hip_yaw_joint" pos="0 0 0" axis="0 0 1" limited="true" range="-100 100" />
                <geom type="mesh" rgba="0.89804 0.91765 0.92941 1" mesh="r_hip_yaw_link" />
                <body name="r_hip_roll_link" pos="-0.002 0 -0.1113">
                    <inertial pos="0.00098497 0.0247755 -0.000158805" quat="0.507267 0.482521 -0.515493 0.494085" mass="2.44028" diaginertia="0.00555319 0.00522044 0.00398529" />
                    <joint name="r_hip_roll_joint" pos="0 0 0" axis="1 0 0" limited="true" range="-100 100" />
                    <geom type="mesh" rgba="0.898039 0.917647 0.929412 1" mesh="r_hip_roll_link" />
                    <body name="r_hip_pitch_link" pos="0 0 0">
                        <inertial pos="-0.00086 0.01229 -0.18794" quat="0.996032 0.086613 -0.0128678 0.0158915" mass="5.27157" diaginertia="0.0494876 0.0415675 0.0148211" />
                        <joint name="r_hip_pitch_joint" pos="0 0 0" axis="0 -1 0" limited="true" range="-100 100" />
                        <geom type="mesh" rgba="0.898039 0.917647 0.929412 1" mesh="r_hip_pitch_link" />
                        <body name="r_knee_link" pos="8.90423e-05 -0.002 -0.360035">
                            <inertial pos="0.01649 0.00164 -0.0869" quat="0.999723 -0.00935451 0.00656552 -0.0205878" mass="2.23575" diaginertia="0.0321048 0.0309597 0.00568988" />
                            <joint name="r_knee_joint" pos="0 0 0" axis="0 -1 0" limited="true" range="-100 100" />
                            <geom type="mesh" rgba="0.898039 0.917647 0.929412 1" mesh="r_knee_link" />
                            <body name="r_ankle_pitch_link" pos="0.000997412 0 -0.350015">
                                <inertial pos="-0.03478 0.00111 -0.00042" quat="0.394661 0.593627 0.377913 0.590789" mass="0.18834" diaginertia="0.000365195 0.000357927 2.92579e-05" />
                                <joint name="r_ankle_pitch_joint" pos="0 0 0" axis="0 1 0" limited="true" range="-100 100" />
                                <geom type="mesh" rgba="0.898039 0.917647 0.929412 1" mesh="r_ankle_pitch_link" />
                                <body name="r_ankle_roll_link" pos="0 0 5.60144e-05">
                                    <inertial pos="0.0261783 0.000138793 -0.0401537" quat="-0.00063479 0.690534 0.0010849 0.723299" mass="1.8066" diaginertia="0.0114808 0.00864049 0.00347388" />
                                    <joint name="r_ankle_roll_joint" pos="0 0 0" axis="-1 0 0" limited="true" range="-100 100" />
                                    <geom type="mesh" rgba="0.898039 0.917647 0.929412 1" mesh="r_ankle_roll_link" />
                                </body>
                            </body>
                        </body>
                    </body>
                </body>
            </body>
            <body name="l_hip_yaw_link" pos="0.016506 0.1 -0.0256">
                <inertial pos="-0.07571 9e-05 -0.09" quat="0.376612 0.597667 0.599307 0.376548" mass="3.1707" diaginertia="0.0193514 0.0168395 0.00710166" />
                <joint name="l_hip_yaw_joint" pos="0 0 0" axis="0 0 1" limited="true" range="-100 100" />
                <geom type="mesh" rgba="1 1 1 1" mesh="l_hip_yaw_link" />
                <body name="l_hip_roll_link" pos="-0.002 0 -0.1113">
                    <inertial pos="0.00085 -0.02478 0.00015" quat="0.483481 0.503785 -0.494629 0.517483" mass="2.43805" diaginertia="0.00555447 0.00521648 0.0039833" />
                    <joint name="l_hip_roll_joint" pos="0 0 0" axis="1 0 0" limited="true" range="-100 100" />
                    <geom type="mesh" rgba="0.898039 0.917647 0.929412 1" mesh="l_hip_roll_link" />
                    <body name="l_hip_pitch_link" pos="0 0 0">
                        <inertial pos="-0.00086 -0.013 -0.18504" quat="0.99698 -0.0751284 -0.0119742 -0.015585" mass="5.61487" diaginertia="0.0504811 0.0426669 0.0152642" />
                        <joint name="l_hip_pitch_joint" pos="0 0 0" axis="0 1 0" limited="true" range="-100 100" />
                        <geom type="mesh" rgba="0.898039 0.917647 0.929412 1" mesh="l_hip_pitch_link" />
                        <body name="l_knee_link" pos="0.00103758 0 -0.359883">
                            <inertial pos="0.01575 -0.00162 -0.08673" quat="0.99964 0.00885815 0.00570931 0.0246636" mass="2.23418" diaginertia="0.0319986 0.0308854 0.00571325" />
                            <joint name="l_knee_joint" pos="0 0 0" axis="0 -1 0" limited="true" range="-100 100" />
                            <geom type="mesh" rgba="0.890196 0.890196 0.913725 1" mesh="l_knee_link" />
                            <body name="l_ankle_pitch_link" pos="0 0 -0.349995">
                                <inertial pos="-0.003478 -0.00112 -0.00042" quat="0.593028 0.374721 0.595629 0.391316" mass="0.18834" diaginertia="0.000365332 0.000357781 2.92577e-05" />
                                <joint name="l_ankle_pitch_joint" pos="0 0 0" axis="0 1 0" limited="true" range="-100 100" />
                                <geom type="mesh" rgba="0.498039 0.498039 0.498039 1" mesh="l_ankle_pitch_link" />
                                <body name="l_ankle_roll_link" pos="0 0 5.60157e-05">
                                    <inertial pos="0.02617 0.00013891 -0.040175" quat="-0.000633409 0.690517 0.00108529 0.723315" mass="1.8051" diaginertia="0.0114776 0.00863905 0.00346976" />
                                    <joint name="l_ankle_roll_joint" pos="0 0 0" axis="-1 0 0" limited="true" range="-100 100" />
                                    <geom type="mesh" rgba="0.89804 0.91765 0.92941 1" mesh="l_ankle_roll_link" />
                                </body>
                            </body>
                        </body>
                    </body>
                </body>
            </body>
        </body>
    </worldbody>

    <actuator>
        <motor gear="100" joint="r_hip_yaw_joint" name="r_hip_yaw"/>
        <motor gear="100" joint="r_hip_roll_joint" name="r_hip_roll"/>
        <motor gear="100" joint="r_hip_pitch_joint" name="r_hip_pitch"/>
        <motor gear="100" joint="r_knee_joint" name="r_knee"/>
        <motor gear="100" joint="r_ankle_pitch_joint" name="r_ankle_pitch"/>
        <motor gear="300" joint="r_ankle_roll_joint" name="r_ankle_roll"/>
        
        <motor gear="100" joint="l_hip_yaw_joint" name="l_hip_yaw"/>
        <motor gear="100" joint="l_hip_roll_joint" name="l_hip_roll"/>
        <motor gear="100" joint="l_hip_pitch_joint" name="l_hip_pitch"/>
        <motor gear="100" joint="l_knee_joint" name="l_knee"/>
        <motor gear="100" joint="l_ankle_pitch_joint" name="l_ankle_pitch"/>
        <motor gear="300" joint="l_ankle_roll_joint" name="l_ankle_roll"/>

    </actuator>

</mujoco>
